Workbook

Sheet D6 Cost Ledger
A1: PE6201 A2 — D6 Final Cost Data and Ledger
A2: Seven submitted model/configuration entries. Monthly ranking uses the five comparable full v2 batteries; Claude is negative-only and GPT-4o mini v1 uses a separate controlled set.
A4: Model | B4: Model ID | C4: Cases | D4: Trials | E4: Passed | F4: Code-check Pass Rate | G4: Approve Passed | H4: Negative Passed | I4: Median Turns | J4: Worst Turns | K4: Input Tokens | L4: Output Tokens | M4: Total Tokens | N4: Layer 1 Total Model Cost (US$) | O4: Layer 1 Cost / Trial (US$) | P4: Expected Fallback / Trial (US$) | Q4: Expected Cost / Trial (Layer 1 + Layer 2, US$) | R4: Difference vs US$7.60 proxy (US$)
A5: GPT-4o mini | B5: openai/gpt-4o-mini | C5: 63 | D5: 109 | E5: 109 | F5: =E5/D5 -> 1 | G5: 40/40 | H5: 69/69 | I5: 4 | J5: 5 | K5: 1369108 | L5: 43694 | M5: =K5+L5 -> 1412802 | N5: =K5/1000000*'D6 Assumptions'!$B$24+L5/1000000*'D6 Assumptions'!$C$24 -> 0.2315826 | O5: =N5/D5 -> 0.002124611 | P5: =(1-F5)*'D6 Assumptions'!$B$6 -> 0 | Q5: =O5+P5 -> 0.002124611 | R5: ='D6 Assumptions'!$B$46-Q5 -> 7.5978754
A6: Gemini 3.8 Flash | B6: google/gemini-3.8-flash | C6: 63 | D6: 109 | E6: 100 | F6: =E6/D6 -> 0.91743119 | G6: 36/40 | H6: 64/69 | I6: 2 | J6: 5 | K6: 1221456 | L6: 212353 | M6: =K6+L6 -> 1433809 | N6: =K6/1000000*'D6 Assumptions'!$B$25+L6/1000000*'D6 Assumptions'!$C$25 -> 1.7124157 | O6: =N6/D6 -> 0.015710236 | P6: =(1-F6)*'D6 Assumptions'!$B$6 -> 0.62752294 | Q6: =O6+P6 -> 0.64323317 | R6: ='D6 Assumptions'!$B$46-Q6 -> 6.9567668
A7: GPT-5.6 Luna | B7: openai/gpt-5.6-luna | C7: 63 | D7: 109 | E7: 108 | F7: =E7/D7 -> 0.99082569 | G7: 40/40 | H7: 68/69 | I7: 2 | J7: 5 | K7: 1301197 | L7: 82200 | M7: =K7+L7 -> 1383397 | N7: =K7/1000000*'D6 Assumptions'!$B$26+L7/1000000*'D6 Assumptions'!$C$26 -> 0.3588794 | O7: =N7/D7 -> 0.0032924716 | P7: =(1-F7)*'D6 Assumptions'!$B$6 -> 0.069724771 | Q7: =O7+P7 -> 0.073017242 | R7: ='D6 Assumptions'!$B$46-Q7 -> 7.5269828
A8: Qwen 3.8 Max | B8: qwen/qwen3.8-max | C8: 63 | D8: 109 | E8: 107 | F8: =E8/D8 -> 0.98165138 | G8: 40/40 | H8: 67/69 | I8: 3 | J8: 4 | K8: 1047715 | L8: 130709 | M8: =K8+L8 -> 1178424 | N8: =K8/1000000*'D6 Assumptions'!$B$27+L8/1000000*'D6 Assumptions'!$C$27 -> 2.879684 | O8: =N8/D8 -> 0.026419119 | P8: =(1-F8)*'D6 Assumptions'!$B$6 -> 0.13944954 | Q8: =O8+P8 -> 0.16586866 | R8: ='D6 Assumptions'!$B$46-Q8 -> 7.4341313
A9: DeepSeek Flash Latest | B9: ~deepseek/deepseek-flash-latest | C9: 63 | D9: 109 | E9: 103 | F9: =E9/D9 -> 0.94495413 | G9: 37/40 | H9: 66/69 | I9: 2 | J9: 5 | K9: 976544 | L9: 69606 | M9: =K9+L9 -> 1046150 | N9: =K9/1000000*'D6 Assumptions'!$B$28+L9/1000000*'D6 Assumptions'!$C$28 -> 0.1882452 | O9: =N9/D9 -> 0.0017270202 | P9: =(1-F9)*'D6 Assumptions'!$B$6 -> 0.41834862 | Q9: =O9+P9 -> 0.42007564 | R9: ='D6 Assumptions'!$B$46-Q9 -> 7.1799244
A10: Claude Sonnet 5 v2 | B10: anthropic/claude-sonnet-5 | C10: 23 | D10: 69 | E10: 69 | F10: =E10/D10 -> 1 | G10: not tested | H10: 69/69 | I10: 2 | J10: 3 | K10: 869849 | L10: 39369 | M10: =K10+L10 -> 909218 | N10: =K10/1000000*'D6 Assumptions'!$B$29+L10/1000000*'D6 Assumptions'!$C$29 -> 2.133388 | O10: =N10/D10 -> 0.030918667 | P10: =(1-F10)*'D6 Assumptions'!$B$6 -> 0 | Q10: =O10+P10 -> 0.030918667 | R10: ='D6 Assumptions'!$B$46-Q10 -> 7.5690813
A11: GPT-4o mini v1 | B11: openai/gpt-4o-mini (v1 configuration) | C11: 15 | D11: 33 | E11: 6 | F11: =E11/D11 -> 0.18181818 | G11: not separated | H11: not separated | K11: 393486 | L11: 11498 | M11: =K11+L11 -> 404984 | N11: =K11/1000000*'D6 Assumptions'!$B$24+L11/1000000*'D6 Assumptions'!$C$24 -> 0.0659217 | O11: =N11/D11 -> 0.0019976273 | P11: =(1-F11)*'D6 Assumptions'!$B$6 -> 6.2181818 | Q11: =O11+P11 -> 6.2201794 | R11: ='D6 Assumptions'!$B$46-Q11 -> 1.3798206

Sheet D6 Assumptions
A1: D6 Assumptions & Cost Formula
A3: Input / Assumption | B3: Value
A4: Manual processing rate (US$/hour) | B4: 38
A5: Manual review time per failed claim (minutes) | B5: 12
A6: Failure / human fallback cost (US$) | B6: =B4*B5/60 -> 7.6
A7: Evaluation cases | B7: 63
A8: Trials per model | B8: 109
A9: Approve trials | B9: 40
A10: Negative trials | B10: 69
A12: Cost formula | B12: Definition
A13: Layer 1 cost / trial | B13: Total repriced model cost ÷ trials
A14: Expected fallback / trial | B14: (1 − code-check pass rate) × US$7.60
A15: Expected cost / trial (Layer 1 + Layer 2) | B15: Layer 1 cost / trial + expected fallback / trial
A17: Data source: WSM's 19 Sep 2026 memo (measured tokens, code-check outcomes and turns). Layer 1 is recalculated from the prices below; raw JSON cost_usd uses uniform rates and is excluded. Costs are uncached token-price estimates, not reconciled billing charges. Code-check pass rates do not replace judgement checks.
A22: Model token prices (US$ per 1M tokens)
A23: Model | B23: Input US$ / 1M | C23: Output US$ / 1M | D23: Price date
A24: GPT-4o mini | B24: 0.15 | C24: 0.6 | D24: 46284
A25: Gemini 3.8 Flash | B25: 0.75 | C25: 3.75 | D25: 46284
A26: GPT-5.6 Luna | B26: 0.2 | C26: 1.2 | D26: 46284
A27: Qwen 3.8 Max | B27: 2 | C27: 6 | D27: 46284
A28: DeepSeek Flash Latest | B28: 0.15 | C28: 0.6 | D28: 46284
A29: Claude Sonnet 5 | B29: 2 | C29: 10 | D29: 46284
A30: Source: OpenRouter pricing pages checked 19 Sep 2026. DeepSeek Flash Latest currently lists US$0.15/M input and US$0.60/M output. Gemini 2.5 Flash is excluded from the formal D6 five-model comparison per the team's latest model selection. No prompt-caching discount is assumed.
A34: Additional D6 inputs | B34: Value | C34: Evidence status
A35: Monthly claim volume | B35: 8000 | C35: Assignment Appendix A p26
A36: Retrieval and external tool fee per task | B36: 0 | C36: Assumed zero for local fixture tools; amend if charged
A37: Storage per month | B37: 20 | C37: Planning assumption: low-volume secure storage and log retention.
A38: Infrastructure per month | B38: 100 | C38: Planning assumption: managed application and database hosting.
A39: Evaluation runs per month | B39: =2*$B$4+'D6 Cost Ledger'!$N$5 -> 76.231583 | C39: Planning assumption: two analyst hours plus one GPT-4o mini full-battery token run each month.
A40: Monitoring per month | B40: =2*$B$4 -> 76 | C40: Planning assumption: two analyst hours per month at US$38/hour.
A41: Maintenance per month | B41: =4*$B$4 -> 152 | C41: Planning assumption: four maintenance hours per month at US$38/hour.
A42: Fixed monthly total K | B42: =SUM(B37:B41) -> 424.23158 | C42: Planning estimate; replace with invoices and time records before deployment.
A43: Step cap | B43: 8 | C43: Observed runtime control.
A44: Per-run budget ceiling | B44: 60000 | C44: Observed MAX_TOKENS_PER_RUN control in the submitted repository.
A45: Monthly limit per user | B45: 200 | C45: Planning cap: 200 claims and US$175 per user per month, whichever is reached first; assumes 40 users.
A46: Manual task cost benchmark | B46: =B6 -> 7.6 | C46: Proxy equals failure handling cost; not measured manual baseline
A47: Success sensitivity change | B47: 0.1 | C47: Required +/-10 percentage points; bounded at 0 and 1
A48: Lower failure cost multiplier | B48: 0.5 | C48: Illustrative sensitivity only
A49: Upper failure cost multiplier | B49: 1.5 | C49: Illustrative sensitivity only
A50: Illustrative monthly fixed cost | B50: =B42 -> 424.23158 | C50: Scenario only; not a measured overhead estimate
...

Sheet B Analysis Handoff
A1: Ready for Part B — Updated Formal Five v2 Models
A3: Model | B3: Code-check Pass Rate | C3: Layer 1 / Trial | D3: Fallback / Trial | E3: Expected Cost / Trial (Layer 1 + Layer 2) | F3: Difference vs manual proxy | G3: Cost as % of manual proxy | H3: Failures / 109 | I3: Median Turns | J3: Notes for Analysis
A4: ='D6 Cost Ledger'!A5 -> GPT-4o mini | B4: ='D6 Cost Ledger'!F5 -> 1 | C4: ='D6 Cost Ledger'!O5 -> 0.002124611 | D4: ='D6 Cost Ledger'!P5 -> 0 | E4: ='D6 Cost Ledger'!Q5 -> 0.002124611 | F4: ='D6 Cost Ledger'!R5 -> 7.5978754 | G4: =E4/'D6 Assumptions'!$B$46 -> 0.00027955408 | H4: ='D6 Cost Ledger'!D5-'D6 Cost Ledger'!E5 -> 0 | I4: ='D6 Cost Ledger'!I5 -> 4 | J4: 109/109 code-check pass; runtime correction still occurred.
A5: ='D6 Cost Ledger'!A6 -> Gemini 3.8 Flash | B5: ='D6 Cost Ledger'!F6 -> 0.91743119 | C5: ='D6 Cost Ledger'!O6 -> 0.015710236 | D5: ='D6 Cost Ledger'!P6 -> 0.62752294 | E5: ='D6 Cost Ledger'!Q6 -> 0.64323317 | F5: ='D6 Cost Ledger'!R6 -> 6.9567668 | G5: =E5/'D6 Assumptions'!$B$46 -> 0.084635944 | H5: ='D6 Cost Ledger'!D6-'D6 Cost Ledger'!E6 -> 9 | I5: ='D6 Cost Ledger'!I6 -> 2 | J5: 100/109; lowest pass rate in formal five and high output-token usage.
A6: ='D6 Cost Ledger'!A7 -> GPT-5.6 Luna | B6: ='D6 Cost Ledger'!F7 -> 0.99082569 | C6: ='D6 Cost Ledger'!O7 -> 0.0032924716 | D6: ='D6 Cost Ledger'!P7 -> 0.069724771 | E6: ='D6 Cost Ledger'!Q7 -> 0.073017242 | F6: ='D6 Cost Ledger'!R7 -> 7.5269828 | G6: =E6/'D6 Assumptions'!$B$46 -> 0.0096075319 | H6: ='D6 Cost Ledger'!D7-'D6 Cost Ledger'!E7 -> 1 | I6: ='D6 Cost Ledger'!I7 -> 2 | J6: 108/109; one negative failure and many final rejections.
A7: ='D6 Cost Ledger'!A8 -> Qwen 3.8 Max | B7: ='D6 Cost Ledger'!F8 -> 0.98165138 | C7: ='D6 Cost Ledger'!O8 -> 0.026419119 | D7: ='D6 Cost Ledger'!P8 -> 0.13944954 | E7: ='D6 Cost Ledger'!Q8 -> 0.16586866 | F7: ='D6 Cost Ledger'!R8 -> 7.4341313 | G7: =E7/'D6 Assumptions'!$B$46 -> 0.021824824 | H7: ='D6 Cost Ledger'!D8-'D6 Cost Ledger'!E8 -> 2 | I7: ='D6 Cost Ledger'!I8 -> 3 | J7: 107/109; two negative failures and the highest Layer 1 token bill.
A8: ='D6 Cost Ledger'!A9 -> DeepSeek Flash Latest | B8: ='D6 Cost Ledger'!F9 -> 0.94495413 | C8: ='D6 Cost Ledger'!O9 -> 0.0017270202 | D8: ='D6 Cost Ledger'!P9 -> 0.41834862 | E8: ='D6 Cost Ledger'!Q9 -> 0.42007564 | F8: ='D6 Cost Ledger'!R9 -> 7.1799244 | G8: =E8/'D6 Assumptions'!$B$46 -> 0.055273111 | H8: ='D6 Cost Ledger'!D9-'D6 Cost Ledger'!E9 -> 6 | I8: ='D6 Cost Ledger'!I9 -> 2 | J8: 103/109; six backend_unavailable stops from empty content. DeepSeek price verified separately for D6.
A12: Sensitivity — Code-check Pass Rate | B12: Expected Cost / Trial | C12: Difference vs manual proxy | D12: Assumed Layer 1 / Trial | F12: Useful interpretation for B
A13: 0.9 | B13: =D13+(1-A13)*'D6 Assumptions'!$B$6 -> 0.76212461 | C13: ='D6 Assumptions'!$B$6-B13 -> 6.8378754 | D13: ='D6 Cost Ledger'!O5 -> 0.002124611 | F13: The human fallback term can dominate token cost: every 1 percentage-point reduction in code-check pass rate adds US$0.076 expected cost per trial (= 1% × US$7.60), before model-token cost. Use the five-model expected costs (Layer 1 + Layer 2) above for the main comparison; the sensitivity table is a scenario illustration.
A14: 0.95 | B14: =D14+(1-A14)*'D6 Assumptions'!$B$6 -> 0.38212461 | C14: ='D6 Assumptions'!$B$6-B14 -> 7.2178754 | D14: ='D6 Cost Ledger'!O5 -> 0.002124611
A15: 0.97 | B15: =D15+(1-A15)*'D6 Assumptions'!$B$6 -> 0.23012461 | C15: ='D6 Assumptions'!$B$6-B15 -> 7.3698754 | D15: ='D6 Cost Ledger'!O5 -> 0.002124611
A16: 0.98 | B16: =D16+(1-A16)*'D6 Assumptions'!$B$6 -> 0.15412461 | C16: ='D6 Assumptions'!$B$6-B16 -> 7.4458754 | D16: ='D6 Cost Ledger'!O5 -> 0.002124611
A17: 0.99 | B17: =D17+(1-A17)*'D6 Assumptions'!$B$6 -> 0.078124611 | C17: ='D6 Assumptions'!$B$6-B17 -> 7.5218754 | D17: ='D6 Cost Ledger'!O5 -> 0.002124611
A18: 0.995 | B18: =D18+(1-A18)*'D6 Assumptions'!$B$6 -> 0.040124611 | C18: ='D6 Assumptions'!$B$6-B18 -> 7.5598754 | D18: ='D6 Cost Ledger'!O5 -> 0.002124611
A19: 1 | B19: =D19+(1-A19)*'D6 Assumptions'!$B$6 -> 0.002124611 | C19: ='D6 Assumptions'!$B$6-B19 -> 7.5978754 | D19: ='D6 Cost Ledger'!O5 -> 0.002124611
A23: The US$7.60 comparator is the assignment failure-handling cost, not a measured manual cost per ordinary claim. Differences are illustrative, not verified ROI.
A24: Formal monthly ranking uses five full v2 batteries. Claude Sonnet 5 (69 negative trials) and GPT-4o mini v1 (33 controlled trials) are costed separately because their scopes differ.

Sheet D6 Analysis
A2: D6 cost analysis and sensitivity
A3: Problem A | US dollars | 8,000 claims/month | 19 Sep 2026 battery | Five comparable full v2 models; Layer 3 planning estimate K is included.
A4: Model | B4: Code pass rate | C4: Variable /task | D4: Fallback /task | E4: Expected /task | F4: Tokens /month | G4: Fallback /month | H4: Subtotal /month | I4: Total incl K | J4: Fallback share
A5: ='D6 Cost Ledger'!A5 -> GPT-4o mini | B5: ='D6 Cost Ledger'!F5 -> 1 | C5: ='D6 Cost Ledger'!O5 -> 0.002124611 | D5: ='D6 Cost Ledger'!P5 -> 0 | E5: ='D6 Cost Ledger'!Q5 -> 0.002124611 | F5: =C5*'D6 Assumptions'!$B$35 -> 16.996888 | G5: =D5*'D6 Assumptions'!$B$35 -> 0 | H5: =E5*'D6 Assumptions'!$B$35 -> 16.996888 | I5: =H5+'D6 Assumptions'!$B$42 -> 441.22847 | J5: =IF(E5=0,0,D5/E5) -> 0
A6: ='D6 Cost Ledger'!A6 -> Gemini 3.8 Flash | B6: ='D6 Cost Ledger'!F6 -> 0.91743119 | C6: ='D6 Cost Ledger'!O6 -> 0.015710236 | D6: ='D6 Cost Ledger'!P6 -> 0.62752294 | E6: ='D6 Cost Ledger'!Q6 -> 0.64323317 | F6: =C6*'D6 Assumptions'!$B$35 -> 125.68189 | G6: =D6*'D6 Assumptions'!$B$35 -> 5020.1835 | H6: =E6*'D6 Assumptions'!$B$35 -> 5145.8654 | I6: =H6+'D6 Assumptions'!$B$42 -> 5570.097 | J6: =IF(E6=0,0,D6/E6) -> 0.97557614
A7: ='D6 Cost Ledger'!A7 -> GPT-5.6 Luna | B7: ='D6 Cost Ledger'!F7 -> 0.99082569 | C7: ='D6 Cost Ledger'!O7 -> 0.0032924716 | D7: ='D6 Cost Ledger'!P7 -> 0.069724771 | E7: ='D6 Cost Ledger'!Q7 -> 0.073017242 | F7: =C7*'D6 Assumptions'!$B$35 -> 26.339772 | G7: =D7*'D6 Assumptions'!$B$35 -> 557.79817 | H7: =E7*'D6 Assumptions'!$B$35 -> 584.13794 | I7: =H7+'D6 Assumptions'!$B$42 -> 1008.3695 | J7: =IF(E7=0,0,D7/E7) -> 0.9549083
A8: ='D6 Cost Ledger'!A8 -> Qwen 3.8 Max | B8: ='D6 Cost Ledger'!F8 -> 0.98165138 | C8: ='D6 Cost Ledger'!O8 -> 0.026419119 | D8: ='D6 Cost Ledger'!P8 -> 0.13944954 | E8: ='D6 Cost Ledger'!Q8 -> 0.16586866 | F8: =C8*'D6 Assumptions'!$B$35 -> 211.35295 | G8: =D8*'D6 Assumptions'!$B$35 -> 1115.5963 | H8: =E8*'D6 Assumptions'!$B$35 -> 1326.9493 | I8: =H8+'D6 Assumptions'!$B$42 -> 1751.1809 | J8: =IF(E8=0,0,D8/E8) -> 0.84072266
A9: ='D6 Cost Ledger'!A9 -> DeepSeek Flash Latest | B9: ='D6 Cost Ledger'!F9 -> 0.94495413 | C9: ='D6 Cost Ledger'!O9 -> 0.0017270202 | D9: ='D6 Cost Ledger'!P9 -> 0.41834862 | E9: ='D6 Cost Ledger'!Q9 -> 0.42007564 | F9: =C9*'D6 Assumptions'!$B$35 -> 13.816161 | G9: =D9*'D6 Assumptions'!$B$35 -> 3346.789 | H9: =E9*'D6 Assumptions'!$B$35 -> 3360.6052 | I9: =H9+'D6 Assumptions'!$B$42 -> 3784.8367 | J9: =IF(E9=0,0,D9/E9) -> 0.99588879
A11: Headline: GPT-4o mini has the lowest modelled monthly total at the observed code-check rate. Fixed costs are planning assumptions and all success rates remain code-check results.
A12: Five-model evaluation token cost | C12: =SUM('D6 Cost Ledger'!N5:N9) -> 5.370807
A13: One-off judgement queue completion budget | C13: ='D6 Assumptions'!$B$78 -> 447.13333
A14: The judgement amount estimates reviewer labour only; it does not imply that the queue has been graded.
A16: Model | B16: Change in p | C16: Scenario p | D16: Variable /task | E16: Fallback /task | F16: Expected /task | G16: Monthly incl K | H16: Change /month
A17: =$A$5 -> GPT-4o mini | B17: -0.1 | C17: =MIN(1,MAX(0,$B$5+B17)) -> 0.9 | D17: =$C$5 -> 0.002124611 | E17: =(1-C17)*'D6 Assumptions'!$B$6 -> 0.76 | F17: =D17+E17 -> 0.76212461 | G17: =F17*'D6 Assumptions'!$B$35+'D6 Assumptions'!$B$42 -> 6521.2285 | H17: =G17-$I$5 -> 6080
A18: =$A$5 -> GPT-4o mini | B18: 0 | C18: =MIN(1,MAX(0,$B$5+B18)) -> 1 | D18: =$C$5 -> 0.002124611 | E18: =(1-C18)*'D6 Assumptions'!$B$6 -> 0 | F18: =D18+E18 -> 0.002124611 | G18: =F18*'D6 Assumptions'!$B$35+'D6 Assumptions'!$B$42 -> 441.22847 | H18: =G18-$I$5 -> 0
A19: =$A$5 -> GPT-4o mini | B19: 0.1 | C19: =MIN(1,MAX(0,$B$5+B19)) -> 1 | D19: =$C$5 -> 0.002124611 | E19: =(1-C19)*'D6 Assumptions'!$B$6 -> 0 | F19: =D19+E19 -> 0.002124611 | G19: =F19*'D6 Assumptions'!$B$35+'D6 Assumptions'!$B$42 -> 441.22847 | H19: =G19-$I$5 -> 0
A20: =$A$6 -> Gemini 3.8 Flash | B20: -0.1 | C20: =MIN(1,MAX(0,$B$6+B20)) -> 0.81743119 | D20: =$C$6 -> 0.015710236 | E20: =(1-C20)*'D6 Assumptions'!$B$6 -> 1.3875229 | F20: =D20+E20 -> 1.4032332 | G20: =F20*'D6 Assumptions'!$B$35+'D6 Assumptions'!$B$42 -> 11650.097 | H20: =G20-$I$6 -> 6080
A21: =$A$6 -> Gemini 3.8 Flash | B21: 0 | C21: =MIN(1,MAX(0,$B$6+B21)) -> 0.91743119 | D21: =$C$6 -> 0.015710236 | E21: =(1-C21)*'D6 Assumptions'!$B$6 -> 0.62752294 | F21: =D21+E21 -> 0.64323317 | G21: =F21*'D6 Assumptions'!$B$35+'D6 Assumptions'!$B$42 -> 5570.097 | H21: =G21-$I$6 -> 0
A22: =$A$6 -> Gemini 3.8 Flash | B22: 0.1 | C22: =MIN(1,MAX(0,$B$6+B22)) -> 1 | D22: =$C$6 -> 0.015710236 | E22: =(1-C22)*'D6 Assumptions'!$B$6 -> 0 | F22: =D22+E22 -> 0.015710236 | G22: =F22*'D6 Assumptions'!$B$35+'D6 Assumptions'!$B$42 -> 549.91347 | H22: =G22-$I$6 -> -5020.1835
A23: =$A$7 -> GPT-5.6 Luna | B23: -0.1 | C23: =MIN(1,MAX(0,$B$7+B23)) -> 0.89082569 | D23: =$C$7 -> 0.0032924716 | E23: =(1-C23)*'D6 Assumptions'!$B$6 -> 0.82972477 | F23: =D23+E23 -> 0.83301724 | G23: =F23*'D6 Assumptions'!$B$35+'D6 Assumptions'!$B$42 -> 7088.3695 | H23: =G23-$I$7 -> 6080
A24: =$A$7 -> GPT-5.6 Luna | B24: 0 | C24: =MIN(1,MAX(0,$B$7+B24)) -> 0.99082569 | D24: =$C$7 -> 0.0032924716 | E24: =(1-C24)*'D6 Assumptions'!$B$6 -> 0.069724771 | F24: =D24+E24 -> 0.073017242 | G24: =F24*'D6 Assumptions'!$B$35+'D6 Assumptions'!$B$42 -> 1008.3695 | H24: =G24-$I$7 -> 0
A25: =$A$7 -> GPT-5.6 Luna | B25: 0.1 | C25: =MIN(1,MAX(0,$B$7+B25)) -> 1 | D25: =$C$7 -> 0.0032924716 | E25: =(1-C25)*'D6 Assumptions'!$B$6 -> 0 | F25: =D25+E25 -> 0.0032924716 | G25: =F25*'D6 Assumptions'!$B$35+'D6 Assumptions'!$B$42 -> 450.57136 | H25: =G25-$I$7 -> -557.79817
A26: =$A$8 -> Qwen 3.8 Max | B26: -0.1 | C26: =MIN(1,MAX(0,$B$8+B26)) -> 0.88165138 | D26: =$C$8 -> 0.026419119 | E26: =(1-C26)*'D6 Assumptions'!$B$6 -> 0.89944954 | F26: =D26+E26 -> 0.92586866 | G26: =F26*'D6 Assumptions'!$B$35+'D6 Assumptions'!$B$42 -> 7831.1809 | H26: =G26-$I$8 -> 6080
A27: =$A$8 -> Qwen 3.8 Max | B27: 0 | C27: =MIN(1,MAX(0,$B$8+B27)) -> 0.98165138 | D27: =$C$8 -> 0.026419119 | E27: =(1-C27)*'D6 Assumptions'!$B$6 -> 0.13944954 | F27: =D27+E27 -> 0.16586866 | G27: =F27*'D6 Assumptions'!$B$35+'D6 Assumptions'!$B$42 -> 1751.1809 | H27: =G27-$I$8 -> 0
A28: =$A$8 -> Qwen 3.8 Max | B28: 0.1 | C28: =MIN(1,MAX(0,$B$8+B28)) -> 1 | D28: =$C$8 -> 0.026419119 | E28: =(1-C28)*'D6 Assumptions'!$B$6 -> 0 | F28: =D28+E28 -> 0.026419119 | G28: =F28*'D6 Assumptions'!$B$35+'D6 Assumptions'!$B$42 -> 635.58454 | H28: =G28-$I$8 -> -1115.5963
A29: =$A$9 -> DeepSeek Flash Latest | B29: -0.1 | C29: =MIN(1,MAX(0,$B$9+B29)) -> 0.84495413 | D29: =$C$9 -> 0.0017270202 | E29: =(1-C29)*'D6 Assumptions'!$B$6 -> 1.1783486 | F29: =D29+E29 -> 1.1800756 | G29: =F29*'D6 Assumptions'!$B$35+'D6 Assumptions'!$B$42 -> 9864.8367 | H29: =G29-$I$9 -> 6080
A30: =$A$9 -> DeepSeek Flash Latest | B30: 0 | C30: =MIN(1,MAX(0,$B$9+B30)) -> 0.94495413 | D30: =$C$9 -> 0.0017270202 | E30: =(1-C30)*'D6 Assumptions'!$B$6 -> 0.41834862 | F30: =D30+E30 -> 0.42007564 | G30: =F30*'D6 Assumptions'!$B$35+'D6 Assumptions'!$B$42 -> 3784.8367 | H30: =G30-$I$9 -> 0
A31: =$A$9 -> DeepSeek Flash Latest | B31: 0.1 | C31: =MIN(1,MAX(0,$B$9+B31)) -> 1 | D31: =$C$9 -> 0.0017270202 | E31: =(1-C31)*'D6 Assumptions'!$B$6 -> 0 | F31: =D31+E31 -> 0.0017270202 | G31: =F31*'D6 Assumptions'!$B$35+'D6 Assumptions'!$B$42 -> 438.04774 | H31: =G31-$I$9 -> -3346.789
A33: A common -10 pp shift preserves the observed cost ordering because every model receives the same US$0.76/task fallback penalty. Independent pass-rate changes can change the ordering.
A36: Comparator | B36: Comparator p | C36: GPT mini C | D36: Comparator E | E36: Mini break-even p | F36: Observed mini p | G36: Headroom pp | H36: Clears threshold
A37: =$A$6 -> Gemini 3.8 Flash | B37: =$B$6 -> 0.91743119 | C37: =$C$5 -> 0.002124611 | D37: =$E$6 -> 0.64323317 | E37: =1-(D37-C37)/'D6 Assumptions'!$B$6 -> 0.91564361 | F37: =$B$5 -> 1 | G37: =(F37-E37)*100 -> 8.435639 | H37: =IF(F37>=E37,"Yes, in sample","No") -> Yes, in sample
A38: =$A$7 -> GPT-5.6 Luna | B38: =$B$7 -> 0.99082569 | C38: =$C$5 -> 0.002124611 | D38: =$E$7 -> 0.073017242 | E38: =1-(D38-C38)/'D6 Assumptions'!$B$6 -> 0.99067202 | F38: =$B$5 -> 1 | G38: =(F38-E38)*100 -> 0.93279778 | H38: =IF(F38>=E38,"Yes, in sample","No") -> Yes, in sample
A39: =$A$8 -> Qwen 3.8 Max | B39: =$B$8 -> 0.98165138 | C39: =$C$5 -> 0.002124611 | D39: =$E$8 -> 0.16586866 | E39: =1-(D39-C39)/'D6 Assumptions'!$B$6 -> 0.97845473 | F39: =$B$5 -> 1 | G39: =(F39-E39)*100 -> 2.154527 | H39: =IF(F39>=E39,"Yes, in sample","No") -> Yes, in sample
A40: =$A$9 -> DeepSeek Flash Latest | B40: =$B$9 -> 0.94495413 | C40: =$C$5 -> 0.002124611 | D40: =$E$9 -> 0.42007564 | E40: =1-(D40-C40)/'D6 Assumptions'!$B$6 -> 0.94500644 | F40: =$B$5 -> 1 | G40: =(F40-E40)*100 -> 5.4993557 | H40: =IF(F40>=E40,"Yes, in sample","No") -> Yes, in sample
A42: Break-even assumes equal fixed costs and comparable task mix. With unequal K, mini p* = 1 - [E - C + (K comparator - K mini)/V]/F.
A45: Mini success p | B45: F = 0.5x | C45: F = 1.0x | D45: F = 1.5x | E45: Monthly cost includes K
A46: Failure cost US$ | B46: ='D6 Assumptions'!$B$6*'D6 Assumptions'!$B$48 -> 3.8 | C46: ='D6 Assumptions'!$B$6 -> 7.6 | D46: ='D6 Assumptions'!$B$6*'D6 Assumptions'!$B$49 -> 11.4
A47: 0.9 | B47: =($C$5+(1-$A47)*B$46)*'D6 Assumptions'!$B$35+'D6 Assumptions'!$B$42 -> 3481.2285 | C47: =($C$5+(1-$A47)*C$46)*'D6 Assumptions'!$B$35+'D6 Assumptions'!$B$42 -> 6521.2285 | D47: =($C$5+(1-$A47)*D$46)*'D6 Assumptions'!$B$35+'D6 Assumptions'!$B$42 -> 9561.2285
A48: 0.95 | B48: =($C$5+(1-$A48)*B$46)*'D6 Assumptions'!$B$35+'D6 Assumptions'!$B$42 -> 1961.2285 | C48: =($C$5+(1-$A48)*C$46)*'D6 Assumptions'!$B$35+'D6 Assumptions'!$B$42 -> 3481.2285 | D48: =($C$5+(1-$A48)*D$46)*'D6 Assumptions'!$B$35+'D6 Assumptions'!$B$42 -> 5001.2285
A49: 0.99 | B49: =($C$5+(1-$A49)*B$46)*'D6 Assumptions'!$B$35+'D6 Assumptions'!$B$42 -> 745.22847 | C49: =($C$5+(1-$A49)*C$46)*'D6 Assumptions'!$B$35+'D6 Assumptions'!$B$42 -> 1049.2285 | D49: =($C$5+(1-$A49)*D$46)*'D6 Assumptions'!$B$35+'D6 Assumptions'!$B$42 -> 1353.2285
...

Sheet D6 Lever Evidence
A2: D6 cost levers and evidence
A3: Source: D2 supplementary tests, 19 Sep 2026. These are separate experiments from the 63-case five-model battery.
A4: Lever | B4: Before | C4: After | D4: Unit | E4: Change | F4: Evidence status
A5: Tool block B | B5: 5317 | C5: 5813 | D5: characters | E5: =C5/B5-1 -> 0.093285687 | F5: Measured characters
A6: Turns T | B6: 9 | C6: 4 | D6: turns | E6: =C6/B6-1 -> -0.55555556 | F6: One scripted case
A7: Observation D | B7: 2897 | C7: 2897 | D7: characters | E7: =C7/B7-1 -> 0 | F7: Controlled scripted path
A8: Success p | B8: 0.18181818 | C8: 0.75757576 | D8: pass rate | E8: =C8-B8 -> 0.57575758 | F8: 15 cases; 33 trials each
A10: Tool tokens before/after are estimates (characters/4), not tokeniser measurements. The tool block increased by 9.3%; no saving is claimed.
A11: Sequential versus parallel: 79,200 vs 24,600 total simulated tokens; 1/1 correct each after relaxing sequential caps. Original sequential cap stopped at 8 turns; 0/1 passed.
A12: Simulated sequential/parallel costs are NOT D6 inputs. Live matched input-token measurements remain missing. Controlled observation size did not change.
A14: Controlled live prompt test | B14: v1 | C14: v2 | D14: Units or interpretation
A15: Trials | B15: 33 | C15: 33 | D15: 15 cases; 9 negative implied
A16: Passed | B16: 6 | C16: 25 | D16: Code checks
A17: Input tokens | B17: 393486 | C17: 648859 | D17: Provider measured
A18: Output tokens | B18: 11498 | C18: 14172 | D18: Provider measured
A19: Raw reported cost | B19: 0.043947 | C19: 0.070559 | D19: Not used for list-price baseline
A20: List-price token cost | B20: =(B17*'D6 Assumptions'!$B$24+B18*'D6 Assumptions'!$C$24)/1000000 -> 0.0659217 | C20: =(C17*'D6 Assumptions'!$B$24+C18*'D6 Assumptions'!$C$24)/1000000 -> 0.10583205 | D20: Repriced at 0.15 / 0.60 per million
A21: Token cost per trial | B21: =B20/B15 -> 0.0019976273 | C21: =C20/C15 -> 0.0032070318 | D21: US$
A22: Measured pass rate | B22: =B16/B15 -> 0.18181818 | C22: =C16/C15 -> 0.75757576 | D22: Separate from five-model battery
A23: Expected cost per task | B23: =B21+(1-B22)*'D6 Assumptions'!$B$6 -> 6.2201794 | C23: =C21+(1-C22)*'D6 Assumptions'!$B$6 -> 1.8456313 | D23: Escalate on failure
A24: Monthly subtotal | B24: =B23*'D6 Assumptions'!$B$35 -> 49761.436 | C24: =C23*'D6 Assumptions'!$B$35 -> 14765.05 | D24: US$, 8,000 claims; excludes K
A25: Observation characters | B25: 62098 | C25: 61296 | D25: Live paths differ
A26: Observation messages | B26: 129 | C26: 128 | D26: Live paths differ
A27: Characters per message | B27: =B25/B26 -> 481.37984 | C27: =C25/C26 -> 478.875 | D27: Derived mean
A29: Monthly saving from v1 to v2 | C29: =B24-C24 -> 34996.385
A31: The observed v1/v2 improvement is 57.58 percentage points. Prompt text and validation strictness changed; attribute the result to the prompt configuration, not wording alone.
A34: Required evidence | B34: Status | C34: What to supply
A35: Fixed monthly costs | B35: Planning assumptions entered | C35: Storage US$20, infrastructure US$100, evaluation US$76.23, monitoring US$76 and maintenance US$152; K = US$424.23/month.
A36: Final run configuration | B36: Partial | C36: Step and budget caps are evidenced; common commit, prompt hash and shared run identifiers still needed.
A37: Judgement checks | B37: Costed; results pending | C37: 353 items × 2 minutes × US$38/hour = US$447.13 one-off. Verdicts and grader identity are still required.
A38: Shipped caps | B38: Observed plus planning cap | C38: 8 turns and 60,000 recorded tokens/run are in the repository. Planning user cap is 200 claims or US$175/month.
A39: Four-lever measurements | B39: Partial | C39: Exact tool/observation tokeniser counts and matched live sequential/parallel input-token measurements still missing.
A40: Operational workload | B40: Missing | C40: Production case mix, correct escalation rate, approval labour and recovery coverage.
A41: Model family / formal v2 set | B41: Team selection updated | C41: Gemini 2.5 Flash removed from the formal five-model D6 comparison; DeepSeek Flash Latest added. Any remaining family-rule interpretation belongs to D5.
A42: Expanded evaluation set | B42: Explain expansion | C42: 63 cases / 109 trials exceed expected 40 / 56; extra runs are allowed, document why.
A43: GPT-4o-mini raw live trace | B43: Supplied | C43: 109 trials / 109 passes; 63 cases; median 4, worst 5 turns; input 1,369,108; output 43,694; config cap=8 turns.
A44: D5 scripted reproducibility | B44: Not established here | C44: D2 supplement shows 1/1 scripted regression; supply the full scripted evaluation set and reproducible repository.
A46: Source reconciliation: 40 ordinary + 23 negative cases = 63 cases; 40 + 23 x 3 = 109 trials. Negative trials are 63.30% of the battery, not an observed production share.
A47: At 100% code-check success, the formula yields zero failure-recovery cost only. Correct escalations and human confirmation may still consume labour and require a separate operational cost model.
A48: The workbook is a completed analytical extension, not a certification of all D0-D7 requirements. See the report for assumptions, derivations and submission actions.
...
